<?xml version="1.0"?>
<robot name="simple_arm" xmlns:xacro="http://www.ros.org/wiki/xacro">

  <link name="base_link">
    <visual>
      <geometry><box size="0.2 0.2 0.1"/></geometry>
      <material name="grey"><color rgba="0.5 0.5 0.5 1"/></material>
    </visual>
  </link>

  <link name="arm_link_1">
    <visual>
      <geometry><box size="0.5 0.1 0.1"/></geometry>
      <origin xyz="0.25 0 0" rpy="0 0 0"/>
      <material name="blue"><color rgba="0 0 1 1"/></material>
    </visual>
  </link>

  <joint name="base_to_arm_1" type="revolute">
    <parent link="base_link"/>
    <child link="arm_link_1"/>
    <origin xyz="0 0 0.05" rpy="0 0 0"/>
    <axis xyz="0 0 1"/>
    <limit lower="-3.14" upper="3.14" velocity="1.0" effort="10.0"/>
  </joint>

</robot>